<?xml version="1.0" ?>
<sdf version="1.7">
    <world name="close_chain_world">
        <physics name="1ms" type="ignored">
            <max_step_size>0.001</max_step_size>
            <real_time_factor>1.0</real_time_factor>
        </physics>
        <plugin
            filename="ignition-gazebo-physics-system"
            name="ignition::gazebo::systems::Physics">
        </plugin>
        <plugin
            filename="ignition-gazebo-user-commands-system"
            name="ignition::gazebo::systems::UserCommands">
        </plugin>
        <plugin
            filename="ignition-gazebo-scene-broadcaster-system"
            name="ignition::gazebo::systems::SceneBroadcaster">
        </plugin>

        <gui fullscreen="0">

            <!-- 3D scene -->
            <plugin filename="GzScene3D" name="3D View">
                <ignition-gui>
                <title>3D View</title>
                <property type="bool" key="showTitleBar">false</property>
                <property type="string" key="state">docked</property>
                </ignition-gui>

                <engine>ogre2</engine>
                <scene>scene</scene>
                <ambient_light>0.4 0.4 0.4</ambient_light>
                <background_color>0.8 0.8 0.8</background_color>
            </plugin>

            <!-- World control -->
            <plugin filename="WorldControl" name="World control">
                <ignition-gui>
                <title>World control</title>
                <property type="bool" key="showTitleBar">false</property>
                <property type="bool" key="resizable">false</property>
                <property type="double" key="height">72</property>
                <property type="double" key="width">121</property>
                <property type="double" key="z">1</property>

                <property type="string" key="state">floating</property>
                <anchors target="3D View">
                    <line own="left" target="left"/>
                    <line own="bottom" target="bottom"/>
                </anchors>
                </ignition-gui>

                <play_pause>true</play_pause>
                <step>true</step>
                <start_paused>true</start_paused>
                <service>/world/car_world/control</service>
                <stats_topic>/world/car_world/stats</stats_topic>
            </plugin>

            <!-- World statistics -->
            <plugin filename="WorldStats" name="World stats">
                <ignition-gui>
                <title>World stats</title>
                <property type="bool" key="showTitleBar">false</property>
                <property type="bool" key="resizable">false</property>
                <property type="double" key="height">110</property>
                <property type="double" key="width">290</property>
                <property type="double" key="z">1</property>

                <property type="string" key="state">floating</property>
                <anchors target="3D View">
                    <line own="right" target="right"/>
                    <line own="bottom" target="bottom"/>
                </anchors>
                </ignition-gui>

                <sim_time>true</sim_time>
                <real_time>true</real_time>
                <real_time_factor>true</real_time_factor>
                <iterations>true</iterations>
                <topic>/world/car_world/stats</topic>

            </plugin>

            <!-- Entity tree -->
            <plugin filename="EntityTree" name="Entity tree">
            </plugin>

        </gui>

        <light type="directional" name="sun">
            <cast_shadows>true</cast_shadows>
            <pose>0 0 10 0 0 0</pose>
            <diffuse>0.8 0.8 0.8 1</diffuse>
            <specular>0.2 0.2 0.2 1</specular>
            <attenuation>
                <range>1000</range>
                <constant>0.9</constant>
                <linear>0.01</linear>
                <quadratic>0.001</quadratic>
            </attenuation>
            <direction>-0.5 0.1 -0.9</direction>
        </light>

        <model name="ground_plane">
            <static>true</static>
            <link name="link">
                <collision name="collision">
                <geometry>
                    <plane>
                    <normal>0 0 1</normal>
                    </plane>
                </geometry>
                </collision>
                <visual name="visual">
                <geometry>
                    <plane>
                    <normal>0 0 1</normal>
                    <size>100 100</size>
                    </plane>
                </geometry>
                <material>
                    <ambient>0.8 0.8 0.8 1</ambient>
                    <diffuse>0.8 0.8 0.8 1</diffuse>
                    <specular>0.8 0.8 0.8 1</specular>
                </material>
                </visual>
            </link>
        </model>

        <model name="closed_chain">

          <link name="right_pad1">
            <self_collide>1</self_collide>
            <pose>0.5 0 0 0 0.0 0</pose>
            <collision name="right_pad1_collision">
              <geometry>
                <box>
                  <size>1.0 1.0 0.1</size>
                </box>
              </geometry>
            </collision>
            <visual name="right_pad1_visual">
              <geometry>
                <box>
                  <size>1.0 1.0 0.1</size>
                </box>
              </geometry>
              <material>
                <script>
                  <uri>file://media/materials/scripts/gazebo.material</uri>
                  <name>Gazebo/Red</name>
                </script>
              </material>
            </visual>
          </link>
          <!-- Joints are respect the CHILD in SDF -->
          <joint type="revolute" name="right_pad_joint1">
            <pose>-0.5 0 0 0 0 0</pose>
            <parent>right_pad1</parent>
            <child>right_pad2</child>
            <axis>
              <xyz>0 1 0</xyz>
            </axis>
          </joint>
          
          
          <link name="right_pad2">
            <self_collide>1</self_collide>
            <pose>1.0 0 0.5 0 -1.5707963268 0</pose>
            <collision name="right_pad2_collision">
              <geometry>
                <box>
                  <size>1.0 1.0 0.1</size>
                </box>
              </geometry>
            </collision>
            <visual name="right_pad2_visual">
              <geometry>
                <box>
                  <size>1.0 1.0 0.1</size>
                </box>
              </geometry>
              <material>
                <script>
                  <uri>file://media/materials/scripts/gazebo.material</uri>
                  <name>Gazebo/Green</name>
                </script>
              </material>
            </visual>
          </link>
          
          
          <joint type="revolute" name="right_pad_joint2">
            <pose>-0.5 0 0 0 0 0</pose>
            <parent>right_pad2</parent>
            <child>right_pad3</child>
            <axis>
              <xyz>0 1 0</xyz>
            </axis>
          </joint>
          
          <link name="right_pad3">
            <self_collide>1</self_collide>
            <pose>0.5 0 1 0 -3.1415926536 0</pose>
            <collision name="right_pad3_collision">
              <geometry>
                <box>
                  <size>1.0 1.0 0.1</size>
                </box>
              </geometry>
            </collision>
            <visual name="right_pad3_visual">
              <geometry>
                <box>
                  <size>1.0 1.0 0.1</size>
                </box>
              </geometry>
              <material>
                <script>
                  <uri>file://media/materials/scripts/gazebo.material</uri>
                  <name>Gazebo/Blue</name>
                </script>
              </material>
            </visual>
          </link>
          
          <joint type="revolute" name="right_pad_joint3">
            <pose>-0.5 0 0 0 0 0</pose>
            <parent>right_pad3</parent>
            <child>right_pad4</child>
            <axis>
              <xyz>0 1 0</xyz>
            </axis>
          </joint>
          
          
          <link name="right_pad4">
            <self_collide>1</self_collide>
            <pose>0 0 0.5 0 -4.7123889804 0</pose>
            <collision name="right_pad4_collision">
              <geometry>
                <box>
                  <size>1.0 1.0 0.1</size>
                </box>
              </geometry>
            </collision>
            <visual name="right_pad4_visual">
              <geometry>
                <box>
                  <size>1.0 1.0 0.1</size>
                </box>
              </geometry>
              <material>
                <script>
                  <uri>file://media/materials/scripts/gazebo.material</uri>
                  <name>Gazebo/Yellow</name>
                </script>
              </material>
            </visual>
          </link>
          
          <joint type="revolute" name="right_pad_joint4">
            <pose>-0.5 0 0 0 0 0</pose>
            <parent>right_pad4</parent>
            <child>right_pad1</child>
            <axis>
              <xyz>0 1 0</xyz>
            </axis>
        </joint>
          
      </model>
    </world>
</sdf>

